Workbook
Name Category: OFFSET(Analysis!XFA1048576,1,0,COUNT(Analysis!XFB:XFB))
Name Categorysales: OFFSET(Analysis!XEZ1048576,1,1,COUNT(Analysis!XFA:XFA))
Name Slicer_CATEGORY_TYPE: #N/A
Name Slicer_MONTH: #N/A
Name Slicer_PAYMENT_MODE: #N/A

Sheet SuperMarket Analysis
A1: Invoice ID | B1: Branch | C1: City | D1: Customer type | E1: Gender | F1: Product line | G1: Unit price | H1: Quantity | I1: Tax 5% | J1: Sales | K1: Date | L1: Time | M1: Payment type | N1: C.O.G.S | O1: gross margin % | P1: gross income | Q1: Rating | R1: Day | S1: Month | T1: Year
A2: 750-67-8428 | B2: Alex | C2: Yangon | D2: Member | E2: Female | F2: Health and beauty | G2: 74.69 | H2: 7 | I2: 26.1415 | J2: 548.9715 | K2: 43586 | L2: 0.54722222 | M2: Ewallet | N2: 522.83 | O2: 4.7619048 | P2: 26.1415 | Q2: 9.1 | R2: =DAY(SuperMarket_Analysis[[#This Row],[Date]]) -> 1 | S2: =TEXT(SuperMarket_Analysis[[#This Row],[Date]],"mmmm") -> May | T2: =YEAR(SuperMarket_Analysis[[#This Row],[Date]]) -> 2019
A3: 226-31-3081 | B3: Giza | C3: Naypyitaw | D3: Normal | E3: Female | F3: Electronic accessories | G3: 15.28 | H3: 5 | I3: 3.82 | J3: 80.22 | K3: 43680 | L3: 0.43680556 | M3: Cash | N3: 76.4 | O3: 4.7619048 | P3: 3.82 | Q3: 9.6 | R3: =DAY(SuperMarket_Analysis[[#This Row],[Date]]) -> 3 | S3: =TEXT(SuperMarket_Analysis[[#This Row],[Date]],"mmmm") -> August | T3: =YEAR(SuperMarket_Analysis[[#This Row],[Date]]) -> 2019
A4: 631-41-3108 | B4: Alex | C4: Yangon | D4: Normal | E4: Female | F4: Home and lifestyle | G4: 46.33 | H4: 7 | I4: 16.2155 | J4: 340.5255 | K4: 43527 | L4: 0.55763889 | M4: Credit card | N4: 324.31 | O4: 4.7619048 | P4: 16.2155 | Q4: 7.4 | R4: =DAY(SuperMarket_Analysis[[#This Row],[Date]]) -> 3 | S4: =TEXT(SuperMarket_Analysis[[#This Row],[Date]],"mmmm") -> March | T4: =YEAR(SuperMarket_Analysis[[#This Row],[Date]]) -> 2019
A5: 123-19-1176 | B5: Alex | C5: Yangon | D5: Member | E5: Female | F5: Health and beauty | G5: 58.22 | H5: 8 | I5: 23.288 | J5: 489.048 | K5: 43492 | L5: 0.85625 | M5: Ewallet | N5: 465.76 | O5: 4.7619048 | P5: 23.288 | Q5: 8.4 | R5: =DAY(SuperMarket_Analysis[[#This Row],[Date]]) -> 27 | S5: =TEXT(SuperMarket_Analysis[[#This Row],[Date]],"mmmm") -> January | T5: =YEAR(SuperMarket_Analysis[[#This Row],[Date]]) -> 2019
A6: 373-73-7910 | B6: Alex | C6: Yangon | D6: Member | E6: Female | F6: Sports and travel | G6: 86.31 | H6: 7 | I6: 30.2085 | J6: 634.3785 | K6: 43549 | L6: 0.44236111 | M6: Ewallet | N6: 604.17 | O6: 4.7619048 | P6: 30.2085 | Q6: 5.3 | R6: =DAY(SuperMarket_Analysis[[#This Row],[Date]]) -> 25 | S6: =TEXT(SuperMarket_Analysis[[#This Row],[Date]],"mmmm") -> March | T6: =YEAR(SuperMarket_Analysis[[#This Row],[Date]]) -> 2019
A7: 699-14-3026 | B7: Giza | C7: Naypyitaw | D7: Member | E7: Female | F7: Electronic accessories | G7: 85.39 | H7: 7 | I7: 29.8865 | J7: 627.6165 | K7: 43521 | L7: 0.77083333 | M7: Ewallet | N7: 597.73 | O7: 4.7619048 | P7: 29.8865 | Q7: 4.1 | R7: =DAY(SuperMarket_Analysis[[#This Row],[Date]]) -> 25 | S7: =TEXT(SuperMarket_Analysis[[#This Row],[Date]],"mmmm") -> February | T7: =YEAR(SuperMarket_Analysis[[#This Row],[Date]]) -> 2019
A8: 355-53-5943 | B8: Alex | C8: Yangon | D8: Member | E8: Female | F8: Electronic accessories | G8: 68.84 | H8: 6 | I8: 20.652 | J8: 433.692 | K8: 43520 | L8: 0.60833333 | M8: Ewallet | N8: 413.04 | O8: 4.7619048 | P8: 20.652 | Q8: 5.8 | R8: =DAY(SuperMarket_Analysis[[#This Row],[Date]]) -> 24 | S8: =TEXT(SuperMarket_Analysis[[#This Row],[Date]],"mmmm") -> February | T8: =YEAR(SuperMarket_Analysis[[#This Row],[Date]]) -> 2019
A9: 315-22-5665 | B9: Giza | C9: Naypyitaw | D9: Member | E9: Female | F9: Home and lifestyle | G9: 73.56 | H9: 10 | I9: 36.78 | J9: 772.38 | K9: 43516 | L9: 0.48472222 | M9: Ewallet | N9: 735.6 | O9: 4.7619048 | P9: 36.78 | Q9: 8 | R9: =DAY(SuperMarket_Analysis[[#This Row],[Date]]) -> 20 | S9: =TEXT(SuperMarket_Analysis[[#This Row],[Date]],"mmmm") -> February | T9: =YEAR(SuperMarket_Analysis[[#This Row],[Date]]) -> 2019
A10: 665-32-9167 | B10: Alex | C10: Yangon | D10: Member | E10: Female | F10: Health and beauty | G10: 36.26 | H10: 2 | I10: 3.626 | J10: 76.146 | K10: 43553 | L10: 0.71875 | M10: Credit card | N10: 72.52 | O10: 4.7619048 | P10: 3.626 | Q10: 7.2 | R10: =DAY(SuperMarket_Analysis[[#This Row],[Date]]) -> 29 | S10: =TEXT(SuperMarket_Analysis[[#This Row],[Date]],"mmmm") -> March | T10: =YEAR(SuperMarket_Analysis[[#This Row],[Date]]) -> 2019
A11: 692-92-5582 | B11: Cairo | C11: Mandalay | D11: Member | E11: Female | F11: Food and beverages | G11: 54.84 | H11: 3 | I11: 8.226 | J11: 172.746 | K11: 43480 | L11: 0.56041667 | M11: Credit card | N11: 164.52 | O11: 4.7619048 | P11: 8.226 | Q11: 5.9 | R11: =DAY(SuperMarket_Analysis[[#This Row],[Date]]) -> 15 | S11: =TEXT(SuperMarket_Analysis[[#This Row],[Date]],"mmmm") -> January | T11: =YEAR(SuperMarket_Analysis[[#This Row],[Date]]) -> 2019
A12: 351-62-0822 | B12: Cairo | C12: Mandalay | D12: Member | E12: Female | F12: Fashion accessories | G12: 14.48 | H12: 4 | I12: 2.896 | J12: 60.816 | K12: 43486 | L12: 0.75486111 | M12: Ewallet | N12: 57.92 | O12: 4.7619048 | P12: 2.896 | Q12: 4.5 | R12: =DAY(SuperMarket_Analysis[[#This Row],[Date]]) -> 21 | S12: =TEXT(SuperMarket_Analysis[[#This Row],[Date]],"mmmm") -> January | T12: =YEAR(SuperMarket_Analysis[[#This Row],[Date]]) -> 2019
A13: 529-56-3974 | B13: Cairo | C13: Mandalay | D13: Member | E13: Female | F13: Electronic accessories | G13: 25.51 | H13: 4 | I13: 5.102 | J13: 107.142 | K13: 43521 | L13: 0.71041667 | M13: Cash | N13: 102.04 | O13: 4.7619048 | P13: 5.102 | Q13: 6.8 | R13: =DAY(SuperMarket_Analysis[[#This Row],[Date]]) -> 25 | S13: =TEXT(SuperMarket_Analysis[[#This Row],[Date]],"mmmm") -> February | T13: =YEAR(SuperMarket_Analysis[[#This Row],[Date]]) -> 2019
... A737: 727-02-1313 | B737: Alex | C737: Yangon | D737: Member | E737: Male | F737: Food and beverages | G737: 31.84 | H737: 1 | I737: 1.592 | J737: 33.432 | K737: 43710 | L737: 0.55694444 | M737: Cash | N737: 31.84 | O737: 4.7619048 | P737: 1.592 | Q737: 7.7 | R737: =DAY(SuperMarket_Analysis[[#This Row],[Date]]) -> 2 | S737: =TEXT(SuperMarket_Analysis[[#This Row],[Date]],"mmmm") -> September | T737: =YEAR(SuperMarket_Analysis[[#This Row],[Date]]) -> 2019

Sheet Input data
A1: DATE | B1: INVOICE ID | C1: QUANTITY | D1: SALE TYPE | E1: PAYMENT MODE | F1: TAX 5% | G1: BRANCH NAME | H1: CATEGORY TYPE | I1: UNIT PRICE | J1: TOTAL C.O.G.S | K1: TOTAL SELLING PRICE | L1: DAY | M1: MONTH | N1: YEAR
A2: =_xlfn.XLOOKUP(B2,SuperMarket_Analysis[Invoice ID],SuperMarket_Analysis[Date]) -> 43586 | B2: 750-67-8428 | C2: =_xlfn.XLOOKUP(B2,SuperMarket_Analysis[Invoice ID],SuperMarket_Analysis[Quantity]) -> 7 | D2: =_xlfn.XLOOKUP('Input data'!B2,'SuperMarket Analysis'!A:A,'SuperMarket Analysis'!F:F) -> Health and beauty | E2: =_xlfn.XLOOKUP(B2,'SuperMarket Analysis'!A:A,'SuperMarket Analysis'!M:M) -> Ewallet | F2: =0.05*Input_Table[[#This Row],[TOTAL C.O.G.S]] -> 26.1415 | G2: =_xlfn.XLOOKUP(Input_Table[[#This Row],[INVOICE ID]],'SuperMarket Analysis'!A:A,'SuperMarket Analysis'!B:B) -> Alex | H2: =_xlfn.XLOOKUP(Input_Table[[#This Row],[INVOICE ID]],'SuperMarket Analysis'!A:A,'SuperMarket Analysis'!F:F) -> Health and beauty | I2: =_xlfn.XLOOKUP(Input_Table[[#This Row],[INVOICE ID]],'SuperMarket Analysis'!A:A,'SuperMarket Analysis'!G:G) -> 74.69 | J2: =_xlfn.XLOOKUP(Input_Table[[#This Row],[INVOICE ID]],'SuperMarket Analysis'!A:A,'SuperMarket Analysis'!N:N) -> 522.83 | K2: =_xlfn.XLOOKUP(Input_Table[[#This Row],[INVOICE ID]],'SuperMarket Analysis'!A:A,'SuperMarket Analysis'!J:J) -> 548.9715 | L2: =DAY(Input_Table[[#This Row],[DATE]]) -> 1 | M2: =TEXT(Input_Table[[#This Row],[DATE]],"mmmm") -> May | N2: =YEAR(Input_Table[[#This Row],[DATE]]) -> 2019
A3: =_xlfn.XLOOKUP(B3,SuperMarket_Analysis[Invoice ID],SuperMarket_Analysis[Date]) -> 43680 | B3: 226-31-3081 | C3: =_xlfn.XLOOKUP(B3,SuperMarket_Analysis[Invoice ID],SuperMarket_Analysis[Quantity]) -> 5 | D3: =_xlfn.XLOOKUP('Input data'!B3,'SuperMarket Analysis'!A:A,'SuperMarket Analysis'!F:F) -> Electronic accessories | E3: =_xlfn.XLOOKUP(B3,'SuperMarket Analysis'!A:A,'SuperMarket Analysis'!M:M) -> Cash | F3: =0.05*Input_Table[[#This Row],[TOTAL C.O.G.S]] -> 3.82 | G3: =_xlfn.XLOOKUP(Input_Table[[#This Row],[INVOICE ID]],'SuperMarket Analysis'!A:A,'SuperMarket Analysis'!B:B) -> Giza | H3: =_xlfn.XLOOKUP(Input_Table[[#This Row],[INVOICE ID]],'SuperMarket Analysis'!A:A,'SuperMarket Analysis'!F:F) -> Electronic accessories | I3: =_xlfn.XLOOKUP(Input_Table[[#This Row],[INVOICE ID]],'SuperMarket Analysis'!A:A,'SuperMarket Analysis'!G:G) -> 15.28 | J3: =_xlfn.XLOOKUP(Input_Table[[#This Row],[INVOICE ID]],'SuperMarket Analysis'!A:A,'SuperMarket Analysis'!N:N) -> 76.4 | K3: =_xlfn.XLOOKUP(Input_Table[[#This Row],[INVOICE ID]],'SuperMarket Analysis'!A:A,'SuperMarket Analysis'!J:J) -> 80.22 | L3: =DAY(Input_Table[[#This Row],[DATE]]) -> 3 | M3: =TEXT(Input_Table[[#This Row],[DATE]],"mmmm") -> August | N3: =YEAR(Input_Table[[#This Row],[DATE]]) -> 2019
A4: =_xlfn.XLOOKUP(B4,SuperMarket_Analysis[Invoice ID],SuperMarket_Analysis[Date]) -> 43527 | B4: 631-41-3108 | C4: =_xlfn.XLOOKUP(B4,SuperMarket_Analysis[Invoice ID],SuperMarket_Analysis[Quantity]) -> 7 | D4: =_xlfn.XLOOKUP('Input data'!B4,'SuperMarket Analysis'!A:A,'SuperMarket Analysis'!F:F) -> Home and lifestyle | E4: =_xlfn.XLOOKUP(B4,'SuperMarket Analysis'!A:A,'SuperMarket Analysis'!M:M) -> Credit card | F4: =0.05*Input_Table[[#This Row],[TOTAL C.O.G.S]] -> 16.2155 | G4: =_xlfn.XLOOKUP(Input_Table[[#This Row],[INVOICE ID]],'SuperMarket Analysis'!A:A,'SuperMarket Analysis'!B:B) -> Alex | H4: =_xlfn.XLOOKUP(Input_Table[[#This Row],[INVOICE ID]],'SuperMarket Analysis'!A:A,'SuperMarket Analysis'!F:F) -> Home and lifestyle | I4: =_xlfn.XLOOKUP(Input_Table[[#This Row],[INVOICE ID]],'SuperMarket Analysis'!A:A,'SuperMarket Analysis'!G:G) -> 46.33 | J4: =_xlfn.XLOOKUP(Input_Table[[#This Row],[INVOICE ID]],'SuperMarket Analysis'!A:A,'SuperMarket Analysis'!N:N) -> 324.31 | K4: =_xlfn.XLOOKUP(Input_Table[[#This Row],[INVOICE ID]],'SuperMarket Analysis'!A:A,'SuperMarket Analysis'!J:J) -> 340.5255 | L4: =DAY(Input_Table[[#This Row],[DATE]]) -> 3 | M4: =TEXT(Input_Table[[#This Row],[DATE]],"mmmm") -> March | N4: =YEAR(Input_Table[[#This Row],[DATE]]) -> 2019
A5: =_xlfn.XLOOKUP(B5,SuperMarket_Analysis[Invoice ID],SuperMarket_Analysis[Date]) -> 43492 | B5: 123-19-1176 | C5: =_xlfn.XLOOKUP(B5,SuperMarket_Analysis[Invoice ID],SuperMarket_Analysis[Quantity]) -> 8 | D5: =_xlfn.XLOOKUP('Input data'!B5,'SuperMarket Analysis'!A:A,'SuperMarket Analysis'!F:F) -> Health and beauty | E5: =_xlfn.XLOOKUP(B5,'SuperMarket Analysis'!A:A,'SuperMarket Analysis'!M:M) -> Ewallet | F5: =0.05*Input_Table[[#This Row],[TOTAL C.O.G.S]] -> 23.288 | G5: =_xlfn.XLOOKUP(Input_Table[[#This Row],[INVOICE ID]],'SuperMarket Analysis'!A:A,'SuperMarket Analysis'!B:B) -> Alex | H5: =_xlfn.XLOOKUP(Input_Table[[#This Row],[INVOICE ID]],'SuperMarket Analysis'!A:A,'SuperMarket Analysis'!F:F) -> Health and beauty | I5: =_xlfn.XLOOKUP(Input_Table[[#This Row],[INVOICE ID]],'SuperMarket Analysis'!A:A,'SuperMarket Analysis'!G:G) -> 58.22 | J5: =_xlfn.XLOOKUP(Input_Table[[#This Row],[INVOICE ID]],'SuperMarket Analysis'!A:A,'SuperMarket Analysis'!N:N) -> 465.76 | K5: =_xlfn.XLOOKUP(Input_Table[[#This Row],[INVOICE ID]],'SuperMarket Analysis'!A:A,'SuperMarket Analysis'!J:J) -> 489.048 | L5: =DAY(Input_Table[[#This Row],[DATE]]) -> 27 | M5: =TEXT(Input_Table[[#This Row],[DATE]],"mmmm") -> January | N5: =YEAR(Input_Table[[#This Row],[DATE]]) -> 2019
A6: =_xlfn.XLOOKUP(B6,SuperMarket_Analysis[Invoice ID],SuperMarket_Analysis[Date]) -> 43549 | B6: 373-73-7910 | C6: =_xlfn.XLOOKUP(B6,SuperMarket_Analysis[Invoice ID],SuperMarket_Analysis[Quantity]) -> 7 | D6: =_xlfn.XLOOKUP('Input data'!B6,'SuperMarket Analysis'!A:A,'SuperMarket Analysis'!F:F) -> Sports and travel | E6: =_xlfn.XLOOKUP(B6,'SuperMarket Analysis'!A:A,'SuperMarket Analysis'!M:M) -> Ewallet | F6: =0.05*Input_Table[[#This Row],[TOTAL C.O.G.S]] -> 30.2085 | G6: =_xlfn.XLOOKUP(Input_Table[[#This Row],[INVOICE ID]],'SuperMarket Analysis'!A:A,'SuperMarket Analysis'!B:B) -> Alex | H6: =_xlfn.XLOOKUP(Input_Table[[#This Row],[INVOICE ID]],'SuperMarket Analysis'!A:A,'SuperMarket Analysis'!F:F) -> Sports and travel | I6: =_xlfn.XLOOKUP(Input_Table[[#This Row],[INVOICE ID]],'SuperMarket Analysis'!A:A,'SuperMarket Analysis'!G:G) -> 86.31 | J6: =_xlfn.XLOOKUP(Input_Table[[#This Row],[INVOICE ID]],'SuperMarket Analysis'!A:A,'SuperMarket Analysis'!N:N) -> 604.17 | K6: =_xlfn.XLOOKUP(Input_Table[[#This Row],[INVOICE ID]],'SuperMarket Analysis'!A:A,'SuperMarket Analysis'!J:J) -> 634.3785 | L6: =DAY(Input_Table[[#This Row],[DATE]]) -> 25 | M6: =TEXT(Input_Table[[#This Row],[DATE]],"mmmm") -> March | N6: =YEAR(Input_Table[[#This Row],[DATE]]) -> 2019
A7: =_xlfn.XLOOKUP(B7,SuperMarket_Analysis[Invoice ID],SuperMarket_Analysis[Date]) -> 43521 | B7: 699-14-3026 | C7: =_xlfn.XLOOKUP(B7,SuperMarket_Analysis[Invoice ID],SuperMarket_Analysis[Quantity]) -> 7 | D7: =_xlfn.XLOOKUP('Input data'!B7,'SuperMarket Analysis'!A:A,'SuperMarket Analysis'!F:F) -> Electronic accessories | E7: =_xlfn.XLOOKUP(B7,'SuperMarket Analysis'!A:A,'SuperMarket Analysis'!M:M) -> Ewallet | F7: =0.05*Input_Table[[#This Row],[TOTAL C.O.G.S]] -> 29.8865 | G7: =_xlfn.XLOOKUP(Input_Table[[#This Row],[INVOICE ID]],'SuperMarket Analysis'!A:A,'SuperMarket Analysis'!B:B) -> Giza | H7: =_xlfn.XLOOKUP(Input_Table[[#This Row],[INVOICE ID]],'SuperMarket Analysis'!A:A,'SuperMarket Analysis'!F:F) -> Electronic accessories | I7: =_xlfn.XLOOKUP(Input_Table[[#This Row],[INVOICE ID]],'SuperMarket Analysis'!A:A,'SuperMarket Analysis'!G:G) -> 85.39 | J7: =_xlfn.XLOOKUP(Input_Table[[#This Row],[INVOICE ID]],'SuperMarket Analysis'!A:A,'SuperMarket Analysis'!N:N) -> 597.73 | K7: =_xlfn.XLOOKUP(Input_Table[[#This Row],[INVOICE ID]],'SuperMarket Analysis'!A:A,'SuperMarket Analysis'!J:J) -> 627.6165 | L7: =DAY(Input_Table[[#This Row],[DATE]]) -> 25 | M7: =TEXT(Input_Table[[#This Row],[DATE]],"mmmm") -> February | N7: =YEAR(Input_Table[[#This Row],[DATE]]) -> 2019
A8: =_xlfn.XLOOKUP(B8,SuperMarket_Analysis[Invoice ID],SuperMarket_Analysis[Date]) -> 43520 | B8: 355-53-5943 | C8: =_xlfn.XLOOKUP(B8,SuperMarket_Analysis[Invoice ID],SuperMarket_Analysis[Quantity]) -> 6 | D8: =_xlfn.XLOOKUP('Input data'!B8,'SuperMarket Analysis'!A:A,'SuperMarket Analysis'!F:F) -> Electronic accessories | E8: =_xlfn.XLOOKUP(B8,'SuperMarket Analysis'!A:A,'SuperMarket Analysis'!M:M) -> Ewallet | F8: =0.05*Input_Table[[#This Row],[TOTAL C.O.G.S]] -> 20.652 | G8: =_xlfn.XLOOKUP(Input_Table[[#This Row],[INVOICE ID]],'SuperMarket Analysis'!A:A,'SuperMarket Analysis'!B:B) -> Alex | H8: =_xlfn.XLOOKUP(Input_Table[[#This Row],[INVOICE ID]],'SuperMarket Analysis'!A:A,'SuperMarket Analysis'!F:F) -> Electronic accessories | I8: =_xlfn.XLOOKUP(Input_Table[[#This Row],[INVOICE ID]],'SuperMarket Analysis'!A:A,'SuperMarket Analysis'!G:G) -> 68.84 | J8: =_xlfn.XLOOKUP(Input_Table[[#This Row],[INVOICE ID]],'SuperMarket Analysis'!A:A,'SuperMarket Analysis'!N:N) -> 413.04 | K8: =_xlfn.XLOOKUP(Input_Table[[#This Row],[INVOICE ID]],'SuperMarket Analysis'!A:A,'SuperMarket Analysis'!J:J) -> 433.692 | L8: =DAY(Input_Table[[#This Row],[DATE]]) -> 24 | M8: =TEXT(Input_Table[[#This Row],[DATE]],"mmmm") -> February | N8: =YEAR(Input_Table[[#This Row],[DATE]]) -> 2019
A9: =_xlfn.XLOOKUP(B9,SuperMarket_Analysis[Invoice ID],SuperMarket_Analysis[Date]) -> 43516 | B9: 315-22-5665 | C9: =_xlfn.XLOOKUP(B9,SuperMarket_Analysis[Invoice ID],SuperMarket_Analysis[Quantity]) -> 10 | D9: =_xlfn.XLOOKUP('Input data'!B9,'SuperMarket Analysis'!A:A,'SuperMarket Analysis'!F:F) -> Home and lifestyle | E9: =_xlfn.XLOOKUP(B9,'SuperMarket Analysis'!A:A,'SuperMarket Analysis'!M:M) -> Ewallet | F9: =0.05*Input_Table[[#This Row],[TOTAL C.O.G.S]] -> 36.78 | G9: =_xlfn.XLOOKUP(Input_Table[[#This Row],[INVOICE ID]],'SuperMarket Analysis'!A:A,'SuperMarket Analysis'!B:B) -> Giza | H9: =_xlfn.XLOOKUP(Input_Table[[#This Row],[INVOICE ID]],'SuperMarket Analysis'!A:A,'SuperMarket Analysis'!F:F) -> Home and lifestyle | I9: =_xlfn.XLOOKUP(Input_Table[[#This Row],[INVOICE ID]],'SuperMarket Analysis'!A:A,'SuperMarket Analysis'!G:G) -> 73.56 | J9: =_xlfn.XLOOKUP(Input_Table[[#This Row],[INVOICE ID]],'SuperMarket Analysis'!A:A,'SuperMarket Analysis'!N:N) -> 735.6 | K9: =_xlfn.XLOOKUP(Input_Table[[#This Row],[INVOICE ID]],'SuperMarket Analysis'!A:A,'SuperMarket Analysis'!J:J) -> 772.38 | L9: =DAY(Input_Table[[#This Row],[DATE]]) -> 20 | M9: =TEXT(Input_Table[[#This Row],[DATE]],"mmmm") -> February | N9: =YEAR(Input_Table[[#This Row],[DATE]]) -> 2019
A10: =_xlfn.XLOOKUP(B10,SuperMarket_Analysis[Invoice ID],SuperMarket_Analysis[Date]) -> 43553 | B10: 665-32-9167 | C10: =_xlfn.XLOOKUP(B10,SuperMarket_Analysis[Invoice ID],SuperMarket_Analysis[Quantity]) -> 2 | D10: =_xlfn.XLOOKUP('Input data'!B10,'SuperMarket Analysis'!A:A,'SuperMarket Analysis'!F:F) -> Health and beauty | E10: =_xlfn.XLOOKUP(B10,'SuperMarket Analysis'!A:A,'SuperMarket Analysis'!M:M) -> Credit card | F10: =0.05*Input_Table[[#This Row],[TOTAL C.O.G.S]] -> 3.626 | G10: =_xlfn.XLOOKUP(Input_Table[[#This Row],[INVOICE ID]],'SuperMarket Analysis'!A:A,'SuperMarket Analysis'!B:B) -> Alex | H10: =_xlfn.XLOOKUP(Input_Table[[#This Row],[INVOICE ID]],'SuperMarket Analysis'!A:A,'SuperMarket Analysis'!F:F) -> Health and beauty | I10: =_xlfn.XLOOKUP(Input_Table[[#This Row],[INVOICE ID]],'SuperMarket Analysis'!A:A,'SuperMarket Analysis'!G:G) -> 36.26 | J10: =_xlfn.XLOOKUP(Input_Table[[#This Row],[INVOICE ID]],'SuperMarket Analysis'!A:A,'SuperMarket Analysis'!N:N) -> 72.52 | K10: =_xlfn.XLOOKUP(Input_Table[[#This Row],[INVOICE ID]],'SuperMarket Analysis'!A:A,'SuperMarket Analysis'!J:J) -> 76.146 | L10: =DAY(Input_Table[[#This Row],[DATE]]) -> 29 | M10: =TEXT(Input_Table[[#This Row],[DATE]],"mmmm") -> March | N10: =YEAR(Input_Table[[#This Row],[DATE]]) -> 2019
A11: =_xlfn.XLOOKUP(B11,SuperMarket_Analysis[Invoice ID],SuperMarket_Analysis[Date]) -> 43480 | B11: 692-92-5582 | C11: =_xlfn.XLOOKUP(B11,SuperMarket_Analysis[Invoice ID],SuperMarket_Analysis[Quantity]) -> 3 | D11: =_xlfn.XLOOKUP('Input data'!B11,'SuperMarket Analysis'!A:A,'SuperMarket Analysis'!F:F) -> Food and beverages | E11: =_xlfn.XLOOKUP(B11,'SuperMarket Analysis'!A:A,'SuperMarket Analysis'!M:M) -> Credit card | F11: =0.05*Input_Table[[#This Row],[TOTAL C.O.G.S]] -> 8.226 | G11: =_xlfn.XLOOKUP(Input_Table[[#This Row],[INVOICE ID]],'SuperMarket Analysis'!A:A,'SuperMarket Analysis'!B:B) -> Cairo | H11: =_xlfn.XLOOKUP(Input_Table[[#This Row],[INVOICE ID]],'SuperMarket Analysis'!A:A,'SuperMarket Analysis'!F:F) -> Food and beverages | I11: =_xlfn.XLOOKUP(Input_Table[[#This Row],[INVOICE ID]],'SuperMarket Analysis'!A:A,'SuperMarket Analysis'!G:G) -> 54.84 | J11: =_xlfn.XLOOKUP(Input_Table[[#This Row],[INVOICE ID]],'SuperMarket Analysis'!A:A,'SuperMarket Analysis'!N:N) -> 164.52 | K11: =_xlfn.XLOOKUP(Input_Table[[#This Row],[INVOICE ID]],'SuperMarket Analysis'!A:A,'SuperMarket Analysis'!J:J) -> 172.746 | L11: =DAY(Input_Table[[#This Row],[DATE]]) -> 15 | M11: =TEXT(Input_Table[[#This Row],[DATE]],"mmmm") -> January | N11: =YEAR(Input_Table[[#This Row],[DATE]]) -> 2019
A12: =_xlfn.XLOOKUP(B12,SuperMarket_Analysis[Invoice ID],SuperMarket_Analysis[Date]) -> 43486 | B12: 351-62-0822 | C12: =_xlfn.XLOOKUP(B12,SuperMarket_Analysis[Invoice ID],SuperMarket_Analysis[Quantity]) -> 4 | D12: =_xlfn.XLOOKUP('Input data'!B12,'SuperMarket Analysis'!A:A,'SuperMarket Analysis'!F:F) -> Fashion accessories | E12: =_xlfn.XLOOKUP(B12,'SuperMarket Analysis'!A:A,'SuperMarket Analysis'!M:M) -> Ewallet | F12: =0.05*Input_Table[[#This Row],[TOTAL C.O.G.S]] -> 2.896 | G12: =_xlfn.XLOOKUP(Input_Table[[#This Row],[INVOICE ID]],'SuperMarket Analysis'!A:A,'SuperMarket Analysis'!B:B) -> Cairo | H12: =_xlfn.XLOOKUP(Input_Table[[#This Row],[INVOICE ID]],'SuperMarket Analysis'!A:A,'SuperMarket Analysis'!F:F) -> Fashion accessories | I12: =_xlfn.XLOOKUP(Input_Table[[#This Row],[INVOICE ID]],'SuperMarket Analysis'!A:A,'SuperMarket Analysis'!G:G) -> 14.48 | J12: =_xlfn.XLOOKUP(Input_Table[[#This Row],[INVOICE ID]],'SuperMarket Analysis'!A:A,'SuperMarket Analysis'!N:N) -> 57.92 | K12: =_xlfn.XLOOKUP(Input_Table[[#This Row],[INVOICE ID]],'SuperMarket Analysis'!A:A,'SuperMarket Analysis'!J:J) -> 60.816 | L12: =DAY(Input_Table[[#This Row],[DATE]]) -> 21 | M12: =TEXT(Input_Table[[#This Row],[DATE]],"mmmm") -> January | N12: =YEAR(Input_Table[[#This Row],[DATE]]) -> 2019
A13: =_xlfn.XLOOKUP(B13,SuperMarket_Analysis[Invoice ID],SuperMarket_Analysis[Date]) -> 43521 | B13: 529-56-3974 | C13: =_xlfn.XLOOKUP(B13,SuperMarket_Analysis[Invoice ID],SuperMarket_Analysis[Quantity]) -> 4 | D13: =_xlfn.XLOOKUP('Input data'!B13,'SuperMarket Analysis'!A:A,'SuperMarket Analysis'!F:F) -> Electronic accessories | E13: =_xlfn.XLOOKUP(B13,'SuperMarket Analysis'!A:A,'SuperMarket Analysis'!M:M) -> Cash | F13: =0.05*Input_Table[[#This Row],[TOTAL C.O.G.S]] -> 5.102 | G13: =_xlfn.XLOOKUP(Input_Table[[#This Row],[INVOICE ID]],'SuperMarket Analysis'!A:A,'SuperMarket Analysis'!B:B) -> Cairo | H13: =_xlfn.XLOOKUP(Input_Table[[#This Row],[INVOICE ID]],'SuperMarket Analysis'!A:A,'SuperMarket Analysis'!F:F) -> Electronic accessories | I13: =_xlfn.XLOOKUP(Input_Table[[#This Row],[INVOICE ID]],'SuperMarket Analysis'!A:A,'SuperMarket Analysis'!G:G) -> 25.51 | J13: =_xlfn.XLOOKUP(Input_Table[[#This Row],[INVOICE ID]],'SuperMarket Analysis'!A:A,'SuperMarket Analysis'!N:N) -> 102.04 | K13: =_xlfn.XLOOKUP(Input_Table[[#This Row],[INVOICE ID]],'SuperMarket Analysis'!A:A,'SuperMarket Analysis'!J:J) -> 107.142 | L13: =DAY(Input_Table[[#This Row],[DATE]]) -> 25 | M13: =TEXT(Input_Table[[#This Row],[DATE]],"mmmm") -> February | N13: =YEAR(Input_Table[[#This Row],[DATE]]) -> 2019
... A737: =_xlfn.XLOOKUP(B737,SuperMarket_Analysis[Invoice ID],SuperMarket_Analysis[Date]) -> 43710 | B737: 727-02-1313 | C737: =_xlfn.XLOOKUP(B737,SuperMarket_Analysis[Invoice ID],SuperMarket_Analysis[Quantity]) -> 1 | D737: =_xlfn.XLOOKUP('Input data'!B737,'SuperMarket Analysis'!A:A,'SuperMarket Analysis'!F:F) -> Food and beverages | E737: =_xlfn.XLOOKUP(B737,'SuperMarket Analysis'!A:A,'SuperMarket Analysis'!M:M) -> Cash | F737: =0.05*Input_Table[[#This Row],[TOTAL C.O.G.S]] -> 1.592 | G737: =_xlfn.XLOOKUP(Input_Table[[#This Row],[INVOICE ID]],'SuperMarket Analysis'!A:A,'SuperMarket Analysis'!B:B) -> Alex | H737: =_xlfn.XLOOKUP(Input_Table[[#This Row],[INVOICE ID]],'SuperMarket Analysis'!A:A,'SuperMarket Analysis'!F:F) -> Food and beverages | I737: =_xlfn.XLOOKUP(Input_Table[[#This Row],[INVOICE ID]],'SuperMarket Analysis'!A:A,'SuperMarket Analysis'!G:G) -> 31.84 | J737: =_xlfn.XLOOKUP(Input_Table[[#This Row],[INVOICE ID]],'SuperMarket Analysis'!A:A,'SuperMarket Analysis'!N:N) -> 31.84 | K737: =_xlfn.XLOOKUP(Input_Table[[#This Row],[INVOICE ID]],'SuperMarket Analysis'!A:A,'SuperMarket Analysis'!J:J) -> 33.432 | L737: =DAY(Input_Table[[#This Row],[DATE]]) -> 2 | M737: =TEXT(Input_Table[[#This Row],[DATE]],"mmmm") -> September | N737: =YEAR(Input_Table[[#This Row],[DATE]]) -> 2019

Sheet Analysis
O1: TRUE | P1: TRUE | Q1: TRUE | X1: =VLOOKUP(1,W:Z,2,0) -> 860-79-0874 | Z1: =CONCATENATE("Kshs. ",VLOOKUP(1,W:Z,3,0)) -> Kshs. 1042.65 | AC1: 1 | AD1: =COUNT(U:U) -> 736 | AE1: =MIN(AC1,AD1) -> 1 | AK1: =VLOOKUP(1,$AJ:$AL,2,0) -> Food and beverages | AL1: =VLOOKUP(1,$AJ:$AL,3,0) -> 43831.105
A2: Day | B2: Total sales | D2: Month | E2: Total sales | G2: TOTAL COGS | H2: TOTAL SALES | J2: Row Labels | K2: Sum of TOTAL C.O.G.S | L2: Sum of TOTAL SELLING PRICE | N2: Month | O2: Sales | P2: Profit | Q2: Profit % | S2: Invoice | T2: Total sales | U2: Units | AG2: Category | AH2: Total Sales | AO2: Payment mode | AP2: Sum of TOTAL SELLING PRICE | AR2: Branch | AS2: Sum of TOTAL SELLING PRICE | AU2: Row Labels | AV2: Sum of TOTAL SELLING PRICE
A3: 1 | B3: 17527.251 | D3: January | E3: 75160.512 | G3: 229176.32 | H3: 240635.14 | J3: January | K3: 71581.44 | L3: 75160.512 | N3: January | O3: =IF($O$1=TRUE,VLOOKUP(N3,J:L,2,0),"N/A") -> 71581.44 | P3: =IF($P$1=TRUE,VLOOKUP(N3,J:L,3,0)-VLOOKUP(N3,J:L,2,0),"N/A") -> 3579.072 | Q3: =IF($Q$1=TRUE,P3/VLOOKUP(N3,J:L,2,0),"") -> 0.05 | S3: 101-17-6199 | T3: 336.5565 | U3: 7 | W3: =RANK(Y:Y,Y:Y) -> 291 | X3: {=OFFSET($S$2,1,0,COUNT(T:T))} -> 101-17-6199 | Y3: {=OFFSET($S$2,1,1,COUNT(T:T))} -> 336.5565 | Z3: {=OFFSET($S$2,1,2,COUNT(T:T))} -> 7 | AC3: {=OFFSET($S$2,AC1,0,10)} -> 101-17-6199 | AD3: {=OFFSET($S$2,AC1,1,10)} -> 336.5565 | AG3: Electronic accessories | AH3: 35711.508 | AJ3: {=RANK(_xlfn.ANCHORARRAY(AL3),_xlfn.ANCHORARRAY(AL3))} -> 5 | AK3: {=OFFSET(AG2,1,0,COUNT(AH:AH))} -> Electronic accessories | AL3: {=OFFSET(AG2,1,1,COUNT(AH:AH))} -> 35711.508 | AO3: Cash | AP3: 85657.309 | AR3: Alex | AS3: 78510.611 | AU3: 01-Jan | AV3: 2142.987
A4: 2 | B4: 15729.893 | D4: February | E4: 59986.238 | J4: February | K4: 57129.75 | L4: 59986.238 | N4: February | O4: =IF($O$1=TRUE,VLOOKUP(N4,J:L,2,0),"N/A") -> 57129.75 | P4: =IF($P$1=TRUE,VLOOKUP(N4,J:L,3,0)-VLOOKUP(N4,J:L,2,0),"N/A") -> 2856.4875 | Q4: =IF($Q$1=TRUE,P4/VLOOKUP(N4,J:L,2,0),"") -> 0.05 | S4: 102-77-2261 | T4: 480.0285 | U4: 7 | W4: =RANK(Y:Y,Y:Y) -> 182 | X4: 102-77-2261 | Y4: 480.0285 | Z4: 7 | AC4: 102-77-2261 | AD4: 480.0285 | AG4: Fashion accessories | AH4: 42210.514 | AJ4: 3 | AK4: Fashion accessories | AL4: 42210.514 | AO4: Credit card | AP4: 77393.568 | AR4: Cairo | AS4: 78728.653 | AU4: 03-Jan | AV4: 674.373
A5: 3 | B5: 15845.896 | D5: March | E5: 68749.275 | G5: Total sales | H5: =GETPIVOTDATA("TOTAL SALES",$G$2) -> 240635.14 | J5: March | K5: 65475.5 | L5: 68749.275 | N5: March | O5: =IF($O$1=TRUE,VLOOKUP(N5,J:L,2,0),"N/A") -> 65475.5 | P5: =IF($P$1=TRUE,VLOOKUP(N5,J:L,3,0)-VLOOKUP(N5,J:L,2,0),"N/A") -> 3273.775 | Q5: =IF($Q$1=TRUE,P5/VLOOKUP(N5,J:L,2,0),"") -> 0.05 | S5: 105-31-1824 | T5: 510.972 | U5: 7 | W5: =RANK(Y:Y,Y:Y) -> 162 | X5: 105-31-1824 | Y5: 510.972 | Z5: 7 | AC5: 105-31-1824 | AD5: 510.972 | AG5: Food and beverages | AH5: 43831.105 | AJ5: 1 | AK5: Food and beverages | AL5: 43831.105 | AO5: Ewallet | AP5: 77584.258 | AR5: Giza | AS5: 83395.872 | AU5: 13-Jan | AV5: 3540.2325
A6: 13 | B6: 9552.921 | D6: April | E6: 2870.4585 | G6: Total profit | H6: =GETPIVOTDATA("TOTAL SALES",$G$2)-GETPIVOTDATA("TOTAL COGS",$G$2) -> 11458.816 | J6: April | K6: 2733.77 | L6: 2870.4585 | N6: April | O6: =IF($O$1=TRUE,VLOOKUP(N6,J:L,2,0),"N/A") -> 2733.77 | P6: =IF($P$1=TRUE,VLOOKUP(N6,J:L,3,0)-VLOOKUP(N6,J:L,2,0),"N/A") -> 136.6885 | Q6: =IF($Q$1=TRUE,P6/VLOOKUP(N6,J:L,2,0),"") -> 0.05 | S6: 106-35-6779 | T6: 93.114 | U6: 2 | W6: =RANK(Y:Y,Y:Y) -> 608 | X6: 106-35-6779 | Y6: 93.114 | Z6: 2 | AC6: 106-35-6779 | AD6: 93.114 | AG6: Health and beauty | AH6: 34723.605 | AJ6: 6 | AK6: Health and beauty | AL6: 34723.605 | AU6: 14-Jan | AV6: 2451.0465
A7: 14 | B7: 10189.851 | D7: May | E7: 5022.255 | G7: Profit % | H7: =H6/GETPIVOTDATA("TOTAL COGS",$G$2) -> 0.05 | J7: May | K7: 4783.1 | L7: 5022.255 | N7: May | O7: =IF($O$1=TRUE,VLOOKUP(N7,J:L,2,0),"N/A") -> 4783.1 | P7: =IF($P$1=TRUE,VLOOKUP(N7,J:L,3,0)-VLOOKUP(N7,J:L,2,0),"N/A") -> 239.155 | Q7: =IF($Q$1=TRUE,P7/VLOOKUP(N7,J:L,2,0),"") -> 0.05 | S7: 109-28-2512 | T7: 614.943 | U7: 6 | W7: =RANK(Y:Y,Y:Y) -> 109 | X7: 109-28-2512 | Y7: 614.943 | Z7: 6 | AC7: 109-28-2512 | AD7: 614.943 | AG7: Home and lifestyle | AH7: 42629.822 | AJ7: 2 | AK7: Home and lifestyle | AL7: 42629.822 | AO7: =AO3 -> Cash | AP7: =AP3 -> 85657.309 | AR7: =AR3 -> Alex | AS7: =AS3 -> 78510.611 | AU7: 15-Jan | AV7: 3860.1885
A8: 15 | B8: 15530.214 | D8: June | E8: 3199.9065 | J8: June | K8: 3047.53 | L8: 3199.9065 | N8: June | O8: =IF($O$1=TRUE,VLOOKUP(N8,J:L,2,0),"N/A") -> 3047.53 | P8: =IF($P$1=TRUE,VLOOKUP(N8,J:L,3,0)-VLOOKUP(N8,J:L,2,0),"N/A") -> 152.3765 | Q8: =IF($Q$1=TRUE,P8/VLOOKUP(N8,J:L,2,0),"") -> 0.05 | S8: 110-05-6330 | T8: 248.409 | U8: 6 | W8: =RANK(Y:Y,Y:Y) -> 381 | X8: 110-05-6330 | Y8: 248.409 | Z8: 6 | AC8: 110-05-6330 | AD8: 248.409 | AG8: Sports and travel | AH8: 41528.581 | AJ8: 4 | AK8: Sports and travel | AL8: 41528.581 | AO8: =AO4 -> Credit card | AP8: =AP4 -> 77393.568 | AR8: =AR4 -> Cairo | AS8: =AS4 -> 78728.653 | AU8: 16-Jan | AV8: 2777.124
A9: 16 | B9: 8864.6565 | D9: July | E9: 3681.993 | J9: July | K9: 3506.66 | L9: 3681.993 | N9: July | O9: =IF($O$1=TRUE,VLOOKUP(N9,J:L,2,0),"N/A") -> 3506.66 | P9: =IF($P$1=TRUE,VLOOKUP(N9,J:L,3,0)-VLOOKUP(N9,J:L,2,0),"N/A") -> 175.333 | Q9: =IF($Q$1=TRUE,P9/VLOOKUP(N9,J:L,2,0),"") -> 0.05 | S9: 110-48-7033 | T9: 137.004 | U9: 4 | W9: =RANK(Y:Y,Y:Y) -> 545 | X9: 110-48-7033 | Y9: 137.004 | Z9: 4 | AC9: 110-48-7033 | AD9: 137.004 | AO9: =AO5 -> Ewallet | AP9: =AP5 -> 77584.258 | AR9: =AR5 -> Giza | AS9: =AS5 -> 83395.872 | AU9: 17-Jan | AV9: 3278.415
A10: 17 | B10: 8843.7405 | D10: August | E10: 3854.109 | J10: August | K10: 3670.58 | L10: 3854.109 | N10: August | O10: =IF($O$1=TRUE,VLOOKUP(N10,J:L,2,0),"N/A") -> 3670.58 | P10: =IF($P$1=TRUE,VLOOKUP(N10,J:L,3,0)-VLOOKUP(N10,J:L,2,0),"N/A") -> 183.529 | Q10: =IF($Q$1=TRUE,P10/VLOOKUP(N10,J:L,2,0),"") -> 0.05 | S10: 114-35-5271 | T10: 486.444 | U10: 8 | W10: =RANK(Y:Y,Y:Y) -> 176 | X10: 114-35-5271 | Y10: 486.444 | Z10: 8 | AC10: 114-35-5271 | AD10: 486.444 | AU10: 18-Jan | AV10: 2982.3255
A11: 18 | B11: 7447.9335 | D11: September | E11: 5680.92 | J11: September | K11: 5410.4 | L11: 5680.92 | N11: September | O11: =IF($O$1=TRUE,VLOOKUP(N11,J:L,2,0),"N/A") -> 5410.4 | P11: =IF($P$1=TRUE,VLOOKUP(N11,J:L,3,0)-VLOOKUP(N11,J:L,2,0),"N/A") -> 270.52 | Q11: =IF($Q$1=TRUE,P11/VLOOKUP(N11,J:L,2,0),"") -> 0.05 | S11: 115-99-4379 | T11: 402.2655 | U11: 7 | W11: =RANK(Y:Y,Y:Y) -> 232 | X11: 115-99-4379 | Y11: 402.2655 | Z11: 7 | AC11: 115-99-4379 | AD11: 402.2655 | AU11: 19-Jan | AV11: 3659.3865
A12: 19 | B12: 11255.044 | D12: October | E12: 3698.3205 | J12: October | K12: 3522.21 | L12: 3698.3205 | N12: October | O12: =IF($O$1=TRUE,VLOOKUP(N12,J:L,2,0),"N/A") -> 3522.21 | P12: =IF($P$1=TRUE,VLOOKUP(N12,J:L,3,0)-VLOOKUP(N12,J:L,2,0),"N/A") -> 176.1105 | Q12: =IF($Q$1=TRUE,P12/VLOOKUP(N12,J:L,2,0),"") -> 0.05 | S12: 120-06-4233 | T12: 192.843 | U12: 6 | W12: =RANK(Y:Y,Y:Y) -> 456 | X12: 120-06-4233 | Y12: 192.843 | Z12: 6 | AC12: 120-06-4233 | AD12: 192.843 | AU12: 20-Jan | AV12: 3205.4715
A13: 20 | B13: 11360.307 | D13: November | E13: 3678.5385 | J13: November | K13: 3503.37 | L13: 3678.5385 | N13: November | O13: =IF($O$1=TRUE,VLOOKUP(N13,J:L,2,0),"N/A") -> 3503.37 | P13: =IF($P$1=TRUE,VLOOKUP(N13,J:L,3,0)-VLOOKUP(N13,J:L,2,0),"N/A") -> 175.1685 | Q13: =IF($Q$1=TRUE,P13/VLOOKUP(N13,J:L,2,0),"") -> 0.05 | S13: 122-61-9553 | T13: 484.974 | U13: 9 | W13: =RANK(Y:Y,Y:Y) -> 179 | X13: 122-61-9553 | Y13: 484.974 | Z13: 9 | AU13: 21-Jan | AV13: 1521.5865
A14: 21 | B14: 7543.1055 | D14: December | E14: 5052.6105 | J14: December | K14: 4812.01 | L14: 5052.6105 | N14: December | O14: =IF($O$1=TRUE,VLOOKUP(N14,J:L,2,0),"N/A") -> 4812.01 | P14: =IF($P$1=TRUE,VLOOKUP(N14,J:L,3,0)-VLOOKUP(N14,J:L,2,0),"N/A") -> 240.6005 | Q14: =IF($Q$1=TRUE,P14/VLOOKUP(N14,J:L,2,0),"") -> 0.05 | S14: 123-19-1176 | T14: 489.048 | U14: 8 | W14: =RANK(Y:Y,Y:Y) -> 174 | X14: 123-19-1176 | Y14: 489.048 | Z14: 8 | AU14: 22-Jan | AV14: 1932.714
A15: 22 | B15: 6951.84 | S15: 124-31-1458 | T15: 250.7085 | U15: 3 | W15: =RANK(Y:Y,Y:Y) -> 380 | X15: 124-31-1458 | Y15: 250.7085 | Z15: 3 | AU15: 23-Jan | AV15: 4465.2405
A16: 23 | B16: 11131.606 | S16: 126-54-1082 | T16: 203.553 | U16: 9 | W16: =RANK(Y:Y,Y:Y) -> 439 | X16: 126-54-1082 | Y16: 203.553 | Z16: 9 | AU16: 24-Jan | AV16: 3793.671
A17: 24 | B17: 10145.247 | S17: 127-47-6963 | T17: 217.182 | U17: 4 | W17: =RANK(Y:Y,Y:Y) -> 412 | X17: 127-47-6963 | Y17: 217.182 | Z17: 4 | AU17: 25-Jan | AV17: 6653.766
A18: 25 | B18: 16146.942 | S18: 129-29-8530 | T18: 328.755 | U18: 5 | W18: =RANK(Y:Y,Y:Y) -> 297 | X18: 129-29-8530 | Y18: 328.755 | Z18: 5 | AU18: 26-Jan | AV18: 3951.78
A19: 26 | B19: 13511.935 | S19: 130-67-4723 | T19: 305.55 | U19: 6 | W19: =RANK(Y:Y,Y:Y) -> 319 | X19: 130-67-4723 | Y19: 305.55 | Z19: 6 | AU19: 27-Jan | AV19: 5273.3625
A20: 27 | B20: 12782.196 | S20: 130-98-8941 | T20: 472.311 | U20: 7 | W20: =RANK(Y:Y,Y:Y) -> 188 | X20: 130-98-8941 | Y20: 472.311 | Z20: 7 | AU20: 28-Jan | AV20: 3710.952
A21: 28 | B21: 9828.3465 | S21: 132-23-6451 | T21: 110.0925 | U21: 5 | W21: =RANK(Y:Y,Y:Y) -> 580 | X21: 132-23-6451 | Y21: 110.0925 | Z21: 5 | AU21: 29-Jan | AV21: 4267.4625
A22: 29 | B22: 6157.473 | S22: 132-32-9879 | T22: 394.632 | U22: 4 | W22: =RANK(Y:Y,Y:Y) -> 242 | X22: 132-32-9879 | Y22: 394.632 | Z22: 4 | AU22: 30-Jan | AV22: 4281.9945
A23: 30 | B23: 7552.3035 | S23: 133-14-7229 | T23: 132.027 | U23: 2 | W23: =RANK(Y:Y,Y:Y) -> 554 | X23: 133-14-7229 | Y23: 132.027 | Z23: 2 | AU23: 31-Jan | AV23: 6736.4325
A24: 31 | B24: 6736.4325 | S24: 134-54-4720 | T24: 356.328 | U24: 8 | W24: =RANK(Y:Y,Y:Y) -> 270 | X24: 134-54-4720 | Y24: 356.328 | Z24: 8 | AU24: 01-Feb | AV24: 547.197
S25: 134-75-2619 | T25: 142.002 | U25: 7 | W25: =RANK(Y:Y,Y:Y) -> 538 | X25: 134-75-2619 | Y25: 142.002 | Z25: 7 | AU25: 02-Feb | AV25: 626.829
S26: 135-84-8019 | T26: 736.4385 | U26: 9 | W26: =RANK(Y:Y,Y:Y) -> 68 | X26: 135-84-8019 | Y26: 736.4385 | Z26: 9 | AU26: 03-Feb | AV26: 3782.2575
S27: 136-08-6195 | T27: 587.664 | U27: 8 | W27: =RANK(Y:Y,Y:Y) -> 120 | X27: 136-08-6195 | Y27: 587.664 | Z27: 8 | AU27: 13-Feb | AV27: 2469.579
S28: 138-17-5109 | T28: 843.0345 | U28: 9 | W28: =RANK(Y:Y,Y:Y) -> 32 | X28: 138-17-5109 | Y28: 843.0345 | Z28: 9 | AU28: 14-Feb | AV28: 1529.8395
S29: 139-20-0155 | T29: 423.15 | U29: 10 | W29: =RANK(Y:Y,Y:Y) -> 218 | X29: 139-20-0155 | Y29: 423.15 | Z29: 10 | AU29: 15-Feb | AV29: 6825.903
S30: 139-52-2867 | T30: 165.4485 | U30: 7 | W30: =RANK(Y:Y,Y:Y) -> 497 | X30: 139-52-2867 | Y30: 165.4485 | Z30: 7 | AU30: 16-Feb | AV30: 2513.1645
S31: 142-63-6033 | T31: 484.89 | U31: 5 | W31: =RANK(Y:Y,Y:Y) -> 180 | X31: 142-63-6033 | Y31: 484.89 | Z31: 5 | AU31: 17-Feb | AV31: 3408.4995
S32: 142-72-4741 | T32: 195.72 | U32: 2 | W32: =RANK(Y:Y,Y:Y) -> 448 | X32: 142-72-4741 | Y32: 195.72 | Z32: 2 | AU32: 18-Feb | AV32: 1906.884
S33: 144-51-6085 | T33: 297.108 | U33: 4 | W33: =RANK(Y:Y,Y:Y) -> 326 | X33: 144-51-6085 | Y33: 297.108 | Z33: 4 | AU33: 19-Feb | AV33: 1835.841
S34: 145-94-9061 | T34: 463.89 | U34: 5 | W34: =RANK(Y:Y,Y:Y) -> 193 | X34: 145-94-9061 | Y34: 463.89 | Z34: 5 | AU34: 20-Feb | AV34: 4486.7655
S35: 146-09-5432 | T35: 331.128 | U35: 9 | W35: =RANK(Y:Y,Y:Y) -> 296 | X35: 146-09-5432 | Y35: 331.128 | Z35: 9 | AU35: 21-Feb | AV35: 3113.7435
S36: 148-82-2527 | T36: 127.26 | U36: 10 | W36: =RANK(Y:Y,Y:Y) -> 560 | X36: 148-82-2527 | Y36: 127.26 | Z36: 10 | AU36: 22-Feb | AV36: 2801.3895
... S89: 214-30-2776 | T89: 181.0725 | U89: 5 | W89: =RANK(Y:Y,Y:Y) -> 473 | X89: 214-30-2776 | Y89: 181.0725 | Z89: 5 | AU89: Grand Total | AV89: 240635.14
S90: 217-58-1179 | T90: 263.13 | U90: 4 | W90: =RANK(Y:Y,Y:Y) -> 366 | X90: 217-58-1179 | Y90: 263.13 | Z90: 4
S91: 218-59-9410 | T91: 228.123 | U91: 3 | W91: =RANK(Y:Y,Y:Y) -> 402 | X91: 218-59-9410 | Y91: 228.123 | Z91: 3
S92: 219-22-9386 | T92: 944.622 | U92: 9 | W92: =RANK(Y:Y,Y:Y) -> 11 | X92: 219-22-9386 | Y92: 944.622 | Z92: 9
...

Sheet Dashboard
O1: FALSE | P1: FALSE | Q1: FALSE | AC1: 1
